2018-03-21 21:30:42,771 - test.py[line:516] - ERROR: msg: division by zero.
Traceback (most recent call last):
  File "/home/alex/PycharmProjects/dangjianyun/dangjiansite/test.py", line 513, in <module>
    1/0
ZeroDivisionError: division by zero
2018-03-22 15:19:54,179 - dangJianCmd.py[line:382] - ERROR: msg: 'NoneType' object is not iterable.
Traceback (most recent call last):
  File "/home/alex/PycharmProjects/dangjianyun/dangjiansite/dangJianCmd.py", line 379, in main
    thumbTen(userobj=userobj, run=run)
  File "/home/alex/PycharmProjects/dangjianyun/dangjiansite/dangJianCmd.py", line 320, in thumbTen
    detail, thumbInfo = run.doThumb(id=id)
TypeError: 'NoneType' object is not iterable
2018-03-23 23:21:02,233 - dangJianCmd.py[line:373] - ERROR: msg: 'NoneType' object is not iterable.
Traceback (most recent call last):
  File "/home/alex/PycharmProjects/dangjianyun/dangjiansite/dangJianCmd.py", line 370, in main
    thumbTen(userobj=userobj, run=run)
  File "/home/alex/PycharmProjects/dangjianyun/dangjiansite/dangJianCmd.py", line 320, in thumbTen
    detail, thumbInfo = run.doThumb(id=id)
TypeError: 'NoneType' object is not iterable
2018-03-24 22:51:51,610 - dangJianCmd.py[line:401] - ERROR: msg: 'NoneType' object is not iterable.
Traceback (most recent call last):
  File "/home/alex/PycharmProjects/dangjianyun/dangjiansite/dangJianCmd.py", line 398, in main
    study(userobj=userobj, run=run)
  File "/home/alex/PycharmProjects/dangjianyun/dangjiansite/dangJianCmd.py", line 256, in study
    run.doStudy(mid=mid)
  File "/home/alex/PycharmProjects/dangjianyun/dangjiansite/runner.py", line 558, in doStudy
    self.studyRsults.update(recordFeeling(content=content))
TypeError: 'NoneType' object is not iterable
2018-03-24 23:22:56,280 - dangJianCmd.py[line:373] - ERROR: msg: ('Connection aborted.', RemoteDisconnected('Remote end closed connection without response',)).
Traceback (most recent call last):
  File "/home/alex/.local/lib/python3.5/site-packages/urllib3/connectionpool.py", line 601, in urlopen
    chunked=chunked)
  File "/home/alex/.local/lib/python3.5/site-packages/urllib3/connectionpool.py", line 387, in _make_request
    six.raise_from(e, None)
  File "<string>", line 2, in raise_from
  File "/home/alex/.local/lib/python3.5/site-packages/urllib3/connectionpool.py", line 383, in _make_request
    httplib_response = conn.getresponse()
  File "/usr/lib/python3.5/http/client.py", line 1197, in getresponse
    response.begin()
  File "/usr/lib/python3.5/http/client.py", line 297, in begin
    version, status, reason = self._read_status()
  File "/usr/lib/python3.5/http/client.py", line 266, in _read_status
    raise RemoteDisconnected("Remote end closed connection without"
http.client.RemoteDisconnected: Remote end closed connection without response

During handling of the above exception, another exception occurred:

Traceback (most recent call last):
  File "/home/alex/.local/lib/python3.5/site-packages/requests/adapters.py", line 440, in send
    timeout=timeout
  File "/home/alex/.local/lib/python3.5/site-packages/urllib3/connectionpool.py", line 639, in urlopen
    _stacktrace=sys.exc_info()[2])
  File "/home/alex/.local/lib/python3.5/site-packages/urllib3/util/retry.py", line 357, in increment
    raise six.reraise(type(error), error, _stacktrace)
  File "/home/alex/.local/lib/python3.5/site-packages/urllib3/packages/six.py", line 685, in reraise
    raise value.with_traceback(tb)
  File "/home/alex/.local/lib/python3.5/site-packages/urllib3/connectionpool.py", line 601, in urlopen
    chunked=chunked)
  File "/home/alex/.local/lib/python3.5/site-packages/urllib3/connectionpool.py", line 387, in _make_request
    six.raise_from(e, None)
  File "<string>", line 2, in raise_from
  File "/home/alex/.local/lib/python3.5/site-packages/urllib3/connectionpool.py", line 383, in _make_request
    httplib_response = conn.getresponse()
  File "/usr/lib/python3.5/http/client.py", line 1197, in getresponse
    response.begin()
  File "/usr/lib/python3.5/http/client.py", line 297, in begin
    version, status, reason = self._read_status()
  File "/usr/lib/python3.5/http/client.py", line 266, in _read_status
    raise RemoteDisconnected("Remote end closed connection without"
urllib3.exceptions.ProtocolError: ('Connection aborted.', RemoteDisconnected('Remote end closed connection without response',))

During handling of the above exception, another exception occurred:

Traceback (most recent call last):
  File "/home/alex/PycharmProjects/dangjianyun/dangjiansite/dangJianCmd.py", line 370, in main
    thumbTen(userobj=userobj, run=run)
  File "/home/alex/PycharmProjects/dangjianyun/dangjiansite/dangJianCmd.py", line 320, in thumbTen
    detail, thumbInfo = run.doThumb(id=id)
  File "/home/alex/PycharmProjects/dangjianyun/dangjiansite/runner.py", line 298, in doThumb
    verify=False).json()
  File "/home/alex/.local/lib/python3.5/site-packages/requests/sessions.py", line 555, in post
    return self.request('POST', url, data=data, json=json, **kwargs)
  File "/home/alex/.local/lib/python3.5/site-packages/requests/sessions.py", line 508, in request
    resp = self.send(prep, **send_kwargs)
  File "/home/alex/.local/lib/python3.5/site-packages/requests/sessions.py", line 618, in send
    r = adapter.send(request, **kwargs)
  File "/home/alex/.local/lib/python3.5/site-packages/requests/adapters.py", line 490, in send
    raise ConnectionError(err, request=request)
requests.exceptions.ConnectionError: ('Connection aborted.', RemoteDisconnected('Remote end closed connection without response',))
2018-03-24 23:24:29,178 - dangJianCmd.py[line:374] - ERROR: msg: ('Connection aborted.', RemoteDisconnected('Remote end closed connection without response',)).
Traceback (most recent call last):
  File "/home/alex/.local/lib/python3.5/site-packages/urllib3/connectionpool.py", line 601, in urlopen
    chunked=chunked)
  File "/home/alex/.local/lib/python3.5/site-packages/urllib3/connectionpool.py", line 387, in _make_request
    six.raise_from(e, None)
  File "<string>", line 2, in raise_from
  File "/home/alex/.local/lib/python3.5/site-packages/urllib3/connectionpool.py", line 383, in _make_request
    httplib_response = conn.getresponse()
  File "/usr/lib/python3.5/http/client.py", line 1197, in getresponse
    response.begin()
  File "/usr/lib/python3.5/http/client.py", line 297, in begin
    version, status, reason = self._read_status()
  File "/usr/lib/python3.5/http/client.py", line 266, in _read_status
    raise RemoteDisconnected("Remote end closed connection without"
http.client.RemoteDisconnected: Remote end closed connection without response

During handling of the above exception, another exception occurred:

Traceback (most recent call last):
  File "/home/alex/.local/lib/python3.5/site-packages/requests/adapters.py", line 440, in send
    timeout=timeout
  File "/home/alex/.local/lib/python3.5/site-packages/urllib3/connectionpool.py", line 639, in urlopen
    _stacktrace=sys.exc_info()[2])
  File "/home/alex/.local/lib/python3.5/site-packages/urllib3/util/retry.py", line 357, in increment
    raise six.reraise(type(error), error, _stacktrace)
  File "/home/alex/.local/lib/python3.5/site-packages/urllib3/packages/six.py", line 685, in reraise
    raise value.with_traceback(tb)
  File "/home/alex/.local/lib/python3.5/site-packages/urllib3/connectionpool.py", line 601, in urlopen
    chunked=chunked)
  File "/home/alex/.local/lib/python3.5/site-packages/urllib3/connectionpool.py", line 387, in _make_request
    six.raise_from(e, None)
  File "<string>", line 2, in raise_from
  File "/home/alex/.local/lib/python3.5/site-packages/urllib3/connectionpool.py", line 383, in _make_request
    httplib_response = conn.getresponse()
  File "/usr/lib/python3.5/http/client.py", line 1197, in getresponse
    response.begin()
  File "/usr/lib/python3.5/http/client.py", line 297, in begin
    version, status, reason = self._read_status()
  File "/usr/lib/python3.5/http/client.py", line 266, in _read_status
    raise RemoteDisconnected("Remote end closed connection without"
urllib3.exceptions.ProtocolError: ('Connection aborted.', RemoteDisconnected('Remote end closed connection without response',))

During handling of the above exception, another exception occurred:

Traceback (most recent call last):
  File "/home/alex/PycharmProjects/dangjianyun/dangjiansite/dangJianCmd.py", line 371, in main
    thumbTen(userobj=userobj, run=run)
  File "/home/alex/PycharmProjects/dangjianyun/dangjiansite/dangJianCmd.py", line 321, in thumbTen
    detail, thumbInfo = run.doThumb(id=id)
  File "/home/alex/PycharmProjects/dangjianyun/dangjiansite/runner.py", line 298, in doThumb
    verify=False).json()
  File "/home/alex/.local/lib/python3.5/site-packages/requests/sessions.py", line 555, in post
    return self.request('POST', url, data=data, json=json, **kwargs)
  File "/home/alex/.local/lib/python3.5/site-packages/requests/sessions.py", line 508, in request
    resp = self.send(prep, **send_kwargs)
  File "/home/alex/.local/lib/python3.5/site-packages/requests/sessions.py", line 618, in send
    r = adapter.send(request, **kwargs)
  File "/home/alex/.local/lib/python3.5/site-packages/requests/adapters.py", line 490, in send
    raise ConnectionError(err, request=request)
requests.exceptions.ConnectionError: ('Connection aborted.', RemoteDisconnected('Remote end closed connection without response',))
2018-03-24 23:27:54,559 - dangJianCmd.py[line:374] - ERROR: msg: ('Connection aborted.', RemoteDisconnected('Remote end closed connection without response',)).
Traceback (most recent call last):
  File "/home/alex/.local/lib/python3.5/site-packages/urllib3/connectionpool.py", line 601, in urlopen
    chunked=chunked)
  File "/home/alex/.local/lib/python3.5/site-packages/urllib3/connectionpool.py", line 387, in _make_request
    six.raise_from(e, None)
  File "<string>", line 2, in raise_from
  File "/home/alex/.local/lib/python3.5/site-packages/urllib3/connectionpool.py", line 383, in _make_request
    httplib_response = conn.getresponse()
  File "/usr/lib/python3.5/http/client.py", line 1197, in getresponse
    response.begin()
  File "/usr/lib/python3.5/http/client.py", line 297, in begin
    version, status, reason = self._read_status()
  File "/usr/lib/python3.5/http/client.py", line 266, in _read_status
    raise RemoteDisconnected("Remote end closed connection without"
http.client.RemoteDisconnected: Remote end closed connection without response

During handling of the above exception, another exception occurred:

Traceback (most recent call last):
  File "/home/alex/.local/lib/python3.5/site-packages/requests/adapters.py", line 440, in send
    timeout=timeout
  File "/home/alex/.local/lib/python3.5/site-packages/urllib3/connectionpool.py", line 639, in urlopen
    _stacktrace=sys.exc_info()[2])
  File "/home/alex/.local/lib/python3.5/site-packages/urllib3/util/retry.py", line 357, in increment
    raise six.reraise(type(error), error, _stacktrace)
  File "/home/alex/.local/lib/python3.5/site-packages/urllib3/packages/six.py", line 685, in reraise
    raise value.with_traceback(tb)
  File "/home/alex/.local/lib/python3.5/site-packages/urllib3/connectionpool.py", line 601, in urlopen
    chunked=chunked)
  File "/home/alex/.local/lib/python3.5/site-packages/urllib3/connectionpool.py", line 387, in _make_request
    six.raise_from(e, None)
  File "<string>", line 2, in raise_from
  File "/home/alex/.local/lib/python3.5/site-packages/urllib3/connectionpool.py", line 383, in _make_request
    httplib_response = conn.getresponse()
  File "/usr/lib/python3.5/http/client.py", line 1197, in getresponse
    response.begin()
  File "/usr/lib/python3.5/http/client.py", line 297, in begin
    version, status, reason = self._read_status()
  File "/usr/lib/python3.5/http/client.py", line 266, in _read_status
    raise RemoteDisconnected("Remote end closed connection without"
urllib3.exceptions.ProtocolError: ('Connection aborted.', RemoteDisconnected('Remote end closed connection without response',))

During handling of the above exception, another exception occurred:

Traceback (most recent call last):
  File "/home/alex/PycharmProjects/dangjianyun/dangjiansite/dangJianCmd.py", line 371, in main
    thumbTen(userobj=userobj, run=run)
  File "/home/alex/PycharmProjects/dangjianyun/dangjiansite/dangJianCmd.py", line 321, in thumbTen
    detail, thumbInfo = run.doThumb(id=id)
  File "/home/alex/PycharmProjects/dangjianyun/dangjiansite/runner.py", line 298, in doThumb
    verify=False).json()
  File "/home/alex/.local/lib/python3.5/site-packages/requests/sessions.py", line 555, in post
    return self.request('POST', url, data=data, json=json, **kwargs)
  File "/home/alex/.local/lib/python3.5/site-packages/requests/sessions.py", line 508, in request
    resp = self.send(prep, **send_kwargs)
  File "/home/alex/.local/lib/python3.5/site-packages/requests/sessions.py", line 618, in send
    r = adapter.send(request, **kwargs)
  File "/home/alex/.local/lib/python3.5/site-packages/requests/adapters.py", line 490, in send
    raise ConnectionError(err, request=request)
requests.exceptions.ConnectionError: ('Connection aborted.', RemoteDisconnected('Remote end closed connection without response',))
2018-03-24 23:28:11,443 - dangJianCmd.py[line:374] - ERROR: msg: ('Connection aborted.', RemoteDisconnected('Remote end closed connection without response',)).
Traceback (most recent call last):
  File "/home/alex/.local/lib/python3.5/site-packages/urllib3/connectionpool.py", line 601, in urlopen
    chunked=chunked)
  File "/home/alex/.local/lib/python3.5/site-packages/urllib3/connectionpool.py", line 387, in _make_request
    six.raise_from(e, None)
  File "<string>", line 2, in raise_from
  File "/home/alex/.local/lib/python3.5/site-packages/urllib3/connectionpool.py", line 383, in _make_request
    httplib_response = conn.getresponse()
  File "/usr/lib/python3.5/http/client.py", line 1197, in getresponse
    response.begin()
  File "/usr/lib/python3.5/http/client.py", line 297, in begin
    version, status, reason = self._read_status()
  File "/usr/lib/python3.5/http/client.py", line 266, in _read_status
    raise RemoteDisconnected("Remote end closed connection without"
http.client.RemoteDisconnected: Remote end closed connection without response

During handling of the above exception, another exception occurred:

Traceback (most recent call last):
  File "/home/alex/.local/lib/python3.5/site-packages/requests/adapters.py", line 440, in send
    timeout=timeout
  File "/home/alex/.local/lib/python3.5/site-packages/urllib3/connectionpool.py", line 639, in urlopen
    _stacktrace=sys.exc_info()[2])
  File "/home/alex/.local/lib/python3.5/site-packages/urllib3/util/retry.py", line 357, in increment
    raise six.reraise(type(error), error, _stacktrace)
  File "/home/alex/.local/lib/python3.5/site-packages/urllib3/packages/six.py", line 685, in reraise
    raise value.with_traceback(tb)
  File "/home/alex/.local/lib/python3.5/site-packages/urllib3/connectionpool.py", line 601, in urlopen
    chunked=chunked)
  File "/home/alex/.local/lib/python3.5/site-packages/urllib3/connectionpool.py", line 387, in _make_request
    six.raise_from(e, None)
  File "<string>", line 2, in raise_from
  File "/home/alex/.local/lib/python3.5/site-packages/urllib3/connectionpool.py", line 383, in _make_request
    httplib_response = conn.getresponse()
  File "/usr/lib/python3.5/http/client.py", line 1197, in getresponse
    response.begin()
  File "/usr/lib/python3.5/http/client.py", line 297, in begin
    version, status, reason = self._read_status()
  File "/usr/lib/python3.5/http/client.py", line 266, in _read_status
    raise RemoteDisconnected("Remote end closed connection without"
urllib3.exceptions.ProtocolError: ('Connection aborted.', RemoteDisconnected('Remote end closed connection without response',))

During handling of the above exception, another exception occurred:

Traceback (most recent call last):
  File "/home/alex/PycharmProjects/dangjianyun/dangjiansite/dangJianCmd.py", line 371, in main
    thumbTen(userobj=userobj, run=run)
  File "/home/alex/PycharmProjects/dangjianyun/dangjiansite/dangJianCmd.py", line 321, in thumbTen
    detail, thumbInfo = run.doThumb(id=id)
  File "/home/alex/PycharmProjects/dangjianyun/dangjiansite/runner.py", line 298, in doThumb
    verify=False).json()
  File "/home/alex/.local/lib/python3.5/site-packages/requests/sessions.py", line 555, in post
    return self.request('POST', url, data=data, json=json, **kwargs)
  File "/home/alex/.local/lib/python3.5/site-packages/requests/sessions.py", line 508, in request
    resp = self.send(prep, **send_kwargs)
  File "/home/alex/.local/lib/python3.5/site-packages/requests/sessions.py", line 618, in send
    r = adapter.send(request, **kwargs)
  File "/home/alex/.local/lib/python3.5/site-packages/requests/adapters.py", line 490, in send
    raise ConnectionError(err, request=request)
requests.exceptions.ConnectionError: ('Connection aborted.', RemoteDisconnected('Remote end closed connection without response',))
2018-03-24 23:28:43,570 - dangJianCmd.py[line:381] - ERROR: msg: ('Connection aborted.', RemoteDisconnected('Remote end closed connection without response',)).
Traceback (most recent call last):
  File "/home/alex/.local/lib/python3.5/site-packages/urllib3/connectionpool.py", line 601, in urlopen
    chunked=chunked)
  File "/home/alex/.local/lib/python3.5/site-packages/urllib3/connectionpool.py", line 387, in _make_request
    six.raise_from(e, None)
  File "<string>", line 2, in raise_from
  File "/home/alex/.local/lib/python3.5/site-packages/urllib3/connectionpool.py", line 383, in _make_request
    httplib_response = conn.getresponse()
  File "/usr/lib/python3.5/http/client.py", line 1197, in getresponse
    response.begin()
  File "/usr/lib/python3.5/http/client.py", line 297, in begin
    version, status, reason = self._read_status()
  File "/usr/lib/python3.5/http/client.py", line 266, in _read_status
    raise RemoteDisconnected("Remote end closed connection without"
http.client.RemoteDisconnected: Remote end closed connection without response

During handling of the above exception, another exception occurred:

Traceback (most recent call last):
  File "/home/alex/.local/lib/python3.5/site-packages/requests/adapters.py", line 440, in send
    timeout=timeout
  File "/home/alex/.local/lib/python3.5/site-packages/urllib3/connectionpool.py", line 639, in urlopen
    _stacktrace=sys.exc_info()[2])
  File "/home/alex/.local/lib/python3.5/site-packages/urllib3/util/retry.py", line 357, in increment
    raise six.reraise(type(error), error, _stacktrace)
  File "/home/alex/.local/lib/python3.5/site-packages/urllib3/packages/six.py", line 685, in reraise
    raise value.with_traceback(tb)
  File "/home/alex/.local/lib/python3.5/site-packages/urllib3/connectionpool.py", line 601, in urlopen
    chunked=chunked)
  File "/home/alex/.local/lib/python3.5/site-packages/urllib3/connectionpool.py", line 387, in _make_request
    six.raise_from(e, None)
  File "<string>", line 2, in raise_from
  File "/home/alex/.local/lib/python3.5/site-packages/urllib3/connectionpool.py", line 383, in _make_request
    httplib_response = conn.getresponse()
  File "/usr/lib/python3.5/http/client.py", line 1197, in getresponse
    response.begin()
  File "/usr/lib/python3.5/http/client.py", line 297, in begin
    version, status, reason = self._read_status()
  File "/usr/lib/python3.5/http/client.py", line 266, in _read_status
    raise RemoteDisconnected("Remote end closed connection without"
urllib3.exceptions.ProtocolError: ('Connection aborted.', RemoteDisconnected('Remote end closed connection without response',))

During handling of the above exception, another exception occurred:

Traceback (most recent call last):
  File "/home/alex/PycharmProjects/dangjianyun/dangjiansite/dangJianCmd.py", line 378, in main
    help(userobj=userobj, run=run)
  File "/home/alex/PycharmProjects/dangjianyun/dangjiansite/dangJianCmd.py", line 158, in help
    helpTimes = run.getExcuteTimes()['help']
  File "/home/alex/PycharmProjects/dangjianyun/dangjiansite/runner.py", line 131, in getExcuteTimes
    credInfo = self.getCredItinfo()
  File "/home/alex/PycharmProjects/dangjianyun/dangjiansite/runner.py", line 231, in getCredItinfo
    info = self.getRJson(url=creditInfourl)
  File "/home/alex/PycharmProjects/dangjianyun/dangjiansite/runner.py", line 189, in getRJson
    return self.session.post(url=url, data=data, verify=False).json()
  File "/home/alex/.local/lib/python3.5/site-packages/requests/sessions.py", line 555, in post
    return self.request('POST', url, data=data, json=json, **kwargs)
  File "/home/alex/.local/lib/python3.5/site-packages/requests/sessions.py", line 508, in request
    resp = self.send(prep, **send_kwargs)
  File "/home/alex/.local/lib/python3.5/site-packages/requests/sessions.py", line 618, in send
    r = adapter.send(request, **kwargs)
  File "/home/alex/.local/lib/python3.5/site-packages/requests/adapters.py", line 490, in send
    raise ConnectionError(err, request=request)
requests.exceptions.ConnectionError: ('Connection aborted.', RemoteDisconnected('Remote end closed connection without response',))
2018-03-25 20:35:45,298 - dangJianCmd.py[line:375] - ERROR: msg: 'NoneType' object is not iterable.
Traceback (most recent call last):
  File "/home/alex/PycharmProjects/dangjianyun/dangjiansite/dangJianCmd.py", line 372, in main
    thumbTen(userobj=userobj, run=run)
  File "/home/alex/PycharmProjects/dangjianyun/dangjiansite/dangJianCmd.py", line 322, in thumbTen
    detail, thumbInfo = run.doThumb(id=id)
TypeError: 'NoneType' object is not iterable
2018-03-25 20:36:02,050 - dangJianCmd.py[line:382] - ERROR: msg: ('Connection aborted.', RemoteDisconnected('Remote end closed connection without response',)).
Traceback (most recent call last):
  File "/home/alex/.local/lib/python3.5/site-packages/urllib3/connectionpool.py", line 601, in urlopen
    chunked=chunked)
  File "/home/alex/.local/lib/python3.5/site-packages/urllib3/connectionpool.py", line 387, in _make_request
    six.raise_from(e, None)
  File "<string>", line 2, in raise_from
  File "/home/alex/.local/lib/python3.5/site-packages/urllib3/connectionpool.py", line 383, in _make_request
    httplib_response = conn.getresponse()
  File "/usr/lib/python3.5/http/client.py", line 1197, in getresponse
    response.begin()
  File "/usr/lib/python3.5/http/client.py", line 297, in begin
    version, status, reason = self._read_status()
  File "/usr/lib/python3.5/http/client.py", line 266, in _read_status
    raise RemoteDisconnected("Remote end closed connection without"
http.client.RemoteDisconnected: Remote end closed connection without response

During handling of the above exception, another exception occurred:

Traceback (most recent call last):
  File "/home/alex/.local/lib/python3.5/site-packages/requests/adapters.py", line 440, in send
    timeout=timeout
  File "/home/alex/.local/lib/python3.5/site-packages/urllib3/connectionpool.py", line 639, in urlopen
    _stacktrace=sys.exc_info()[2])
  File "/home/alex/.local/lib/python3.5/site-packages/urllib3/util/retry.py", line 357, in increment
    raise six.reraise(type(error), error, _stacktrace)
  File "/home/alex/.local/lib/python3.5/site-packages/urllib3/packages/six.py", line 685, in reraise
    raise value.with_traceback(tb)
  File "/home/alex/.local/lib/python3.5/site-packages/urllib3/connectionpool.py", line 601, in urlopen
    chunked=chunked)
  File "/home/alex/.local/lib/python3.5/site-packages/urllib3/connectionpool.py", line 387, in _make_request
    six.raise_from(e, None)
  File "<string>", line 2, in raise_from
  File "/home/alex/.local/lib/python3.5/site-packages/urllib3/connectionpool.py", line 383, in _make_request
    httplib_response = conn.getresponse()
  File "/usr/lib/python3.5/http/client.py", line 1197, in getresponse
    response.begin()
  File "/usr/lib/python3.5/http/client.py", line 297, in begin
    version, status, reason = self._read_status()
  File "/usr/lib/python3.5/http/client.py", line 266, in _read_status
    raise RemoteDisconnected("Remote end closed connection without"
urllib3.exceptions.ProtocolError: ('Connection aborted.', RemoteDisconnected('Remote end closed connection without response',))

During handling of the above exception, another exception occurred:

Traceback (most recent call last):
  File "/home/alex/PycharmProjects/dangjianyun/dangjiansite/dangJianCmd.py", line 379, in main
    help(userobj=userobj, run=run)
  File "/home/alex/PycharmProjects/dangjianyun/dangjiansite/dangJianCmd.py", line 158, in help
    helpTimes = run.getExcuteTimes()['help']
  File "/home/alex/PycharmProjects/dangjianyun/dangjiansite/runner.py", line 132, in getExcuteTimes
    credInfo = self.getCredItinfo()
  File "/home/alex/PycharmProjects/dangjianyun/dangjiansite/runner.py", line 232, in getCredItinfo
    info = self.getRJson(url=creditInfourl)
  File "/home/alex/PycharmProjects/dangjianyun/dangjiansite/runner.py", line 190, in getRJson
    return self.session.post(url=url, data=data, verify=False).json()
  File "/home/alex/.local/lib/python3.5/site-packages/requests/sessions.py", line 555, in post
    return self.request('POST', url, data=data, json=json, **kwargs)
  File "/home/alex/.local/lib/python3.5/site-packages/requests/sessions.py", line 508, in request
    resp = self.send(prep, **send_kwargs)
  File "/home/alex/.local/lib/python3.5/site-packages/requests/sessions.py", line 618, in send
    r = adapter.send(request, **kwargs)
  File "/home/alex/.local/lib/python3.5/site-packages/requests/adapters.py", line 490, in send
    raise ConnectionError(err, request=request)
requests.exceptions.ConnectionError: ('Connection aborted.', RemoteDisconnected('Remote end closed connection without response',))
2018-03-25 20:40:50,908 - dangJianCmd.py[line:376] - ERROR: msg: ('Connection aborted.', RemoteDisconnected('Remote end closed connection without response',)).
Traceback (most recent call last):
  File "/home/alex/.local/lib/python3.5/site-packages/urllib3/connectionpool.py", line 601, in urlopen
    chunked=chunked)
  File "/home/alex/.local/lib/python3.5/site-packages/urllib3/connectionpool.py", line 387, in _make_request
    six.raise_from(e, None)
  File "<string>", line 2, in raise_from
  File "/home/alex/.local/lib/python3.5/site-packages/urllib3/connectionpool.py", line 383, in _make_request
    httplib_response = conn.getresponse()
  File "/usr/lib/python3.5/http/client.py", line 1197, in getresponse
    response.begin()
  File "/usr/lib/python3.5/http/client.py", line 297, in begin
    version, status, reason = self._read_status()
  File "/usr/lib/python3.5/http/client.py", line 266, in _read_status
    raise RemoteDisconnected("Remote end closed connection without"
http.client.RemoteDisconnected: Remote end closed connection without response

During handling of the above exception, another exception occurred:

Traceback (most recent call last):
  File "/home/alex/.local/lib/python3.5/site-packages/requests/adapters.py", line 440, in send
    timeout=timeout
  File "/home/alex/.local/lib/python3.5/site-packages/urllib3/connectionpool.py", line 639, in urlopen
    _stacktrace=sys.exc_info()[2])
  File "/home/alex/.local/lib/python3.5/site-packages/urllib3/util/retry.py", line 357, in increment
    raise six.reraise(type(error), error, _stacktrace)
  File "/home/alex/.local/lib/python3.5/site-packages/urllib3/packages/six.py", line 685, in reraise
    raise value.with_traceback(tb)
  File "/home/alex/.local/lib/python3.5/site-packages/urllib3/connectionpool.py", line 601, in urlopen
    chunked=chunked)
  File "/home/alex/.local/lib/python3.5/site-packages/urllib3/connectionpool.py", line 387, in _make_request
    six.raise_from(e, None)
  File "<string>", line 2, in raise_from
  File "/home/alex/.local/lib/python3.5/site-packages/urllib3/connectionpool.py", line 383, in _make_request
    httplib_response = conn.getresponse()
  File "/usr/lib/python3.5/http/client.py", line 1197, in getresponse
    response.begin()
  File "/usr/lib/python3.5/http/client.py", line 297, in begin
    version, status, reason = self._read_status()
  File "/usr/lib/python3.5/http/client.py", line 266, in _read_status
    raise RemoteDisconnected("Remote end closed connection without"
urllib3.exceptions.ProtocolError: ('Connection aborted.', RemoteDisconnected('Remote end closed connection without response',))

During handling of the above exception, another exception occurred:

Traceback (most recent call last):
  File "/home/alex/PycharmProjects/dangjianyun/dangjiansite/dangJianCmd.py", line 373, in main
    thumbTen(userobj=userobj, run=run)
  File "/home/alex/PycharmProjects/dangjianyun/dangjiansite/dangJianCmd.py", line 322, in thumbTen
    detail, thumbInfo = run.doThumb(id=id)
  File "/home/alex/PycharmProjects/dangjianyun/dangjiansite/runner.py", line 299, in doThumb
    verify=False).json()
  File "/home/alex/.local/lib/python3.5/site-packages/requests/sessions.py", line 555, in post
    return self.request('POST', url, data=data, json=json, **kwargs)
  File "/home/alex/.local/lib/python3.5/site-packages/requests/sessions.py", line 508, in request
    resp = self.send(prep, **send_kwargs)
  File "/home/alex/.local/lib/python3.5/site-packages/requests/sessions.py", line 618, in send
    r = adapter.send(request, **kwargs)
  File "/home/alex/.local/lib/python3.5/site-packages/requests/adapters.py", line 490, in send
    raise ConnectionError(err, request=request)
requests.exceptions.ConnectionError: ('Connection aborted.', RemoteDisconnected('Remote end closed connection without response',))
2018-03-25 20:41:51,413 - dangJianCmd.py[line:376] - ERROR: msg: ('Connection aborted.', RemoteDisconnected('Remote end closed connection without response',)).
Traceback (most recent call last):
  File "/home/alex/.local/lib/python3.5/site-packages/urllib3/connectionpool.py", line 601, in urlopen
    chunked=chunked)
  File "/home/alex/.local/lib/python3.5/site-packages/urllib3/connectionpool.py", line 387, in _make_request
    six.raise_from(e, None)
  File "<string>", line 2, in raise_from
  File "/home/alex/.local/lib/python3.5/site-packages/urllib3/connectionpool.py", line 383, in _make_request
    httplib_response = conn.getresponse()
  File "/usr/lib/python3.5/http/client.py", line 1197, in getresponse
    response.begin()
  File "/usr/lib/python3.5/http/client.py", line 297, in begin
    version, status, reason = self._read_status()
  File "/usr/lib/python3.5/http/client.py", line 266, in _read_status
    raise RemoteDisconnected("Remote end closed connection without"
http.client.RemoteDisconnected: Remote end closed connection without response

During handling of the above exception, another exception occurred:

Traceback (most recent call last):
  File "/home/alex/.local/lib/python3.5/site-packages/requests/adapters.py", line 440, in send
    timeout=timeout
  File "/home/alex/.local/lib/python3.5/site-packages/urllib3/connectionpool.py", line 639, in urlopen
    _stacktrace=sys.exc_info()[2])
  File "/home/alex/.local/lib/python3.5/site-packages/urllib3/util/retry.py", line 357, in increment
    raise six.reraise(type(error), error, _stacktrace)
  File "/home/alex/.local/lib/python3.5/site-packages/urllib3/packages/six.py", line 685, in reraise
    raise value.with_traceback(tb)
  File "/home/alex/.local/lib/python3.5/site-packages/urllib3/connectionpool.py", line 601, in urlopen
    chunked=chunked)
  File "/home/alex/.local/lib/python3.5/site-packages/urllib3/connectionpool.py", line 387, in _make_request
    six.raise_from(e, None)
  File "<string>", line 2, in raise_from
  File "/home/alex/.local/lib/python3.5/site-packages/urllib3/connectionpool.py", line 383, in _make_request
    httplib_response = conn.getresponse()
  File "/usr/lib/python3.5/http/client.py", line 1197, in getresponse
    response.begin()
  File "/usr/lib/python3.5/http/client.py", line 297, in begin
    version, status, reason = self._read_status()
  File "/usr/lib/python3.5/http/client.py", line 266, in _read_status
    raise RemoteDisconnected("Remote end closed connection without"
urllib3.exceptions.ProtocolError: ('Connection aborted.', RemoteDisconnected('Remote end closed connection without response',))

During handling of the above exception, another exception occurred:

Traceback (most recent call last):
  File "/home/alex/PycharmProjects/dangjianyun/dangjiansite/dangJianCmd.py", line 373, in main
    thumbTen(userobj=userobj, run=run)
  File "/home/alex/PycharmProjects/dangjianyun/dangjiansite/dangJianCmd.py", line 322, in thumbTen
    detail, thumbInfo = run.doThumb(id=id)
  File "/home/alex/PycharmProjects/dangjianyun/dangjiansite/runner.py", line 299, in doThumb
    verify=False).json()
  File "/home/alex/.local/lib/python3.5/site-packages/requests/sessions.py", line 555, in post
    return self.request('POST', url, data=data, json=json, **kwargs)
  File "/home/alex/.local/lib/python3.5/site-packages/requests/sessions.py", line 508, in request
    resp = self.send(prep, **send_kwargs)
  File "/home/alex/.local/lib/python3.5/site-packages/requests/sessions.py", line 618, in send
    r = adapter.send(request, **kwargs)
  File "/home/alex/.local/lib/python3.5/site-packages/requests/adapters.py", line 490, in send
    raise ConnectionError(err, request=request)
requests.exceptions.ConnectionError: ('Connection aborted.', RemoteDisconnected('Remote end closed connection without response',))
2018-03-26 20:05:40,794 - dangJianCmd.py[line:380] - ERROR: msg: ('Connection aborted.', RemoteDisconnected('Remote end closed connection without response',)).
Traceback (most recent call last):
  File "/home/alex/.local/lib/python3.5/site-packages/urllib3/connectionpool.py", line 601, in urlopen
    chunked=chunked)
  File "/home/alex/.local/lib/python3.5/site-packages/urllib3/connectionpool.py", line 387, in _make_request
    six.raise_from(e, None)
  File "<string>", line 2, in raise_from
  File "/home/alex/.local/lib/python3.5/site-packages/urllib3/connectionpool.py", line 383, in _make_request
    httplib_response = conn.getresponse()
  File "/usr/lib/python3.5/http/client.py", line 1197, in getresponse
    response.begin()
  File "/usr/lib/python3.5/http/client.py", line 297, in begin
    version, status, reason = self._read_status()
  File "/usr/lib/python3.5/http/client.py", line 266, in _read_status
    raise RemoteDisconnected("Remote end closed connection without"
http.client.RemoteDisconnected: Remote end closed connection without response

During handling of the above exception, another exception occurred:

Traceback (most recent call last):
  File "/home/alex/.local/lib/python3.5/site-packages/requests/adapters.py", line 440, in send
    timeout=timeout
  File "/home/alex/.local/lib/python3.5/site-packages/urllib3/connectionpool.py", line 639, in urlopen
    _stacktrace=sys.exc_info()[2])
  File "/home/alex/.local/lib/python3.5/site-packages/urllib3/util/retry.py", line 357, in increment
    raise six.reraise(type(error), error, _stacktrace)
  File "/home/alex/.local/lib/python3.5/site-packages/urllib3/packages/six.py", line 685, in reraise
    raise value.with_traceback(tb)
  File "/home/alex/.local/lib/python3.5/site-packages/urllib3/connectionpool.py", line 601, in urlopen
    chunked=chunked)
  File "/home/alex/.local/lib/python3.5/site-packages/urllib3/connectionpool.py", line 387, in _make_request
    six.raise_from(e, None)
  File "<string>", line 2, in raise_from
  File "/home/alex/.local/lib/python3.5/site-packages/urllib3/connectionpool.py", line 383, in _make_request
    httplib_response = conn.getresponse()
  File "/usr/lib/python3.5/http/client.py", line 1197, in getresponse
    response.begin()
  File "/usr/lib/python3.5/http/client.py", line 297, in begin
    version, status, reason = self._read_status()
  File "/usr/lib/python3.5/http/client.py", line 266, in _read_status
    raise RemoteDisconnected("Remote end closed connection without"
urllib3.exceptions.ProtocolError: ('Connection aborted.', RemoteDisconnected('Remote end closed connection without response',))

During handling of the above exception, another exception occurred:

Traceback (most recent call last):
  File "/home/alex/PycharmProjects/dangjianyun/dangjiansite/dangJianCmd.py", line 377, in main
    thumbTen(userobj=userobj, run=run)
  File "/home/alex/PycharmProjects/dangjianyun/dangjiansite/dangJianCmd.py", line 312, in thumbTen
    while run.getExcuteTimes()['thumb'] > 0:
  File "/home/alex/PycharmProjects/dangjianyun/dangjiansite/runner.py", line 132, in getExcuteTimes
    credInfo = self.getCredItinfo()
  File "/home/alex/PycharmProjects/dangjianyun/dangjiansite/runner.py", line 232, in getCredItinfo
    info = self.getRJson(url=creditInfourl)
  File "/home/alex/PycharmProjects/dangjianyun/dangjiansite/runner.py", line 190, in getRJson
    return self.session.post(url=url, data=data, verify=False).json()
  File "/home/alex/.local/lib/python3.5/site-packages/requests/sessions.py", line 555, in post
    return self.request('POST', url, data=data, json=json, **kwargs)
  File "/home/alex/.local/lib/python3.5/site-packages/requests/sessions.py", line 508, in request
    resp = self.send(prep, **send_kwargs)
  File "/home/alex/.local/lib/python3.5/site-packages/requests/sessions.py", line 618, in send
    r = adapter.send(request, **kwargs)
  File "/home/alex/.local/lib/python3.5/site-packages/requests/adapters.py", line 490, in send
    raise ConnectionError(err, request=request)
requests.exceptions.ConnectionError: ('Connection aborted.', RemoteDisconnected('Remote end closed connection without response',))
2018-03-26 20:06:40,994 - dangJianCmd.py[line:380] - ERROR: msg: ('Connection aborted.', RemoteDisconnected('Remote end closed connection without response',)).
Traceback (most recent call last):
  File "/home/alex/.local/lib/python3.5/site-packages/urllib3/connectionpool.py", line 601, in urlopen
    chunked=chunked)
  File "/home/alex/.local/lib/python3.5/site-packages/urllib3/connectionpool.py", line 387, in _make_request
    six.raise_from(e, None)
  File "<string>", line 2, in raise_from
  File "/home/alex/.local/lib/python3.5/site-packages/urllib3/connectionpool.py", line 383, in _make_request
    httplib_response = conn.getresponse()
  File "/usr/lib/python3.5/http/client.py", line 1197, in getresponse
    response.begin()
  File "/usr/lib/python3.5/http/client.py", line 297, in begin
    version, status, reason = self._read_status()
  File "/usr/lib/python3.5/http/client.py", line 266, in _read_status
    raise RemoteDisconnected("Remote end closed connection without"
http.client.RemoteDisconnected: Remote end closed connection without response

During handling of the above exception, another exception occurred:

Traceback (most recent call last):
  File "/home/alex/.local/lib/python3.5/site-packages/requests/adapters.py", line 440, in send
    timeout=timeout
  File "/home/alex/.local/lib/python3.5/site-packages/urllib3/connectionpool.py", line 639, in urlopen
    _stacktrace=sys.exc_info()[2])
  File "/home/alex/.local/lib/python3.5/site-packages/urllib3/util/retry.py", line 357, in increment
    raise six.reraise(type(error), error, _stacktrace)
  File "/home/alex/.local/lib/python3.5/site-packages/urllib3/packages/six.py", line 685, in reraise
    raise value.with_traceback(tb)
  File "/home/alex/.local/lib/python3.5/site-packages/urllib3/connectionpool.py", line 601, in urlopen
    chunked=chunked)
  File "/home/alex/.local/lib/python3.5/site-packages/urllib3/connectionpool.py", line 387, in _make_request
    six.raise_from(e, None)
  File "<string>", line 2, in raise_from
  File "/home/alex/.local/lib/python3.5/site-packages/urllib3/connectionpool.py", line 383, in _make_request
    httplib_response = conn.getresponse()
  File "/usr/lib/python3.5/http/client.py", line 1197, in getresponse
    response.begin()
  File "/usr/lib/python3.5/http/client.py", line 297, in begin
    version, status, reason = self._read_status()
  File "/usr/lib/python3.5/http/client.py", line 266, in _read_status
    raise RemoteDisconnected("Remote end closed connection without"
urllib3.exceptions.ProtocolError: ('Connection aborted.', RemoteDisconnected('Remote end closed connection without response',))

During handling of the above exception, another exception occurred:

Traceback (most recent call last):
  File "/home/alex/PycharmProjects/dangjianyun/dangjiansite/dangJianCmd.py", line 377, in main
    thumbTen(userobj=userobj, run=run)
  File "/home/alex/PycharmProjects/dangjianyun/dangjiansite/dangJianCmd.py", line 312, in thumbTen
    while run.getExcuteTimes()['thumb'] > 0:
  File "/home/alex/PycharmProjects/dangjianyun/dangjiansite/runner.py", line 132, in getExcuteTimes
    credInfo = self.getCredItinfo()
  File "/home/alex/PycharmProjects/dangjianyun/dangjiansite/runner.py", line 232, in getCredItinfo
    info = self.getRJson(url=creditInfourl)
  File "/home/alex/PycharmProjects/dangjianyun/dangjiansite/runner.py", line 190, in getRJson
    return self.session.post(url=url, data=data, verify=False).json()
  File "/home/alex/.local/lib/python3.5/site-packages/requests/sessions.py", line 555, in post
    return self.request('POST', url, data=data, json=json, **kwargs)
  File "/home/alex/.local/lib/python3.5/site-packages/requests/sessions.py", line 508, in request
    resp = self.send(prep, **send_kwargs)
  File "/home/alex/.local/lib/python3.5/site-packages/requests/sessions.py", line 618, in send
    r = adapter.send(request, **kwargs)
  File "/home/alex/.local/lib/python3.5/site-packages/requests/adapters.py", line 490, in send
    raise ConnectionError(err, request=request)
requests.exceptions.ConnectionError: ('Connection aborted.', RemoteDisconnected('Remote end closed connection without response',))
2018-03-26 20:07:04,340 - dangJianCmd.py[line:380] - ERROR: msg: ('Connection aborted.', RemoteDisconnected('Remote end closed connection without response',)).
Traceback (most recent call last):
  File "/home/alex/.local/lib/python3.5/site-packages/urllib3/connectionpool.py", line 601, in urlopen
    chunked=chunked)
  File "/home/alex/.local/lib/python3.5/site-packages/urllib3/connectionpool.py", line 387, in _make_request
    six.raise_from(e, None)
  File "<string>", line 2, in raise_from
  File "/home/alex/.local/lib/python3.5/site-packages/urllib3/connectionpool.py", line 383, in _make_request
    httplib_response = conn.getresponse()
  File "/usr/lib/python3.5/http/client.py", line 1197, in getresponse
    response.begin()
  File "/usr/lib/python3.5/http/client.py", line 297, in begin
    version, status, reason = self._read_status()
  File "/usr/lib/python3.5/http/client.py", line 266, in _read_status
    raise RemoteDisconnected("Remote end closed connection without"
http.client.RemoteDisconnected: Remote end closed connection without response

During handling of the above exception, another exception occurred:

Traceback (most recent call last):
  File "/home/alex/.local/lib/python3.5/site-packages/requests/adapters.py", line 440, in send
    timeout=timeout
  File "/home/alex/.local/lib/python3.5/site-packages/urllib3/connectionpool.py", line 639, in urlopen
    _stacktrace=sys.exc_info()[2])
  File "/home/alex/.local/lib/python3.5/site-packages/urllib3/util/retry.py", line 357, in increment
    raise six.reraise(type(error), error, _stacktrace)
  File "/home/alex/.local/lib/python3.5/site-packages/urllib3/packages/six.py", line 685, in reraise
    raise value.with_traceback(tb)
  File "/home/alex/.local/lib/python3.5/site-packages/urllib3/connectionpool.py", line 601, in urlopen
    chunked=chunked)
  File "/home/alex/.local/lib/python3.5/site-packages/urllib3/connectionpool.py", line 387, in _make_request
    six.raise_from(e, None)
  File "<string>", line 2, in raise_from
  File "/home/alex/.local/lib/python3.5/site-packages/urllib3/connectionpool.py", line 383, in _make_request
    httplib_response = conn.getresponse()
  File "/usr/lib/python3.5/http/client.py", line 1197, in getresponse
    response.begin()
  File "/usr/lib/python3.5/http/client.py", line 297, in begin
    version, status, reason = self._read_status()
  File "/usr/lib/python3.5/http/client.py", line 266, in _read_status
    raise RemoteDisconnected("Remote end closed connection without"
urllib3.exceptions.ProtocolError: ('Connection aborted.', RemoteDisconnected('Remote end closed connection without response',))

During handling of the above exception, another exception occurred:

Traceback (most recent call last):
  File "/home/alex/PycharmProjects/dangjianyun/dangjiansite/dangJianCmd.py", line 377, in main
    thumbTen(userobj=userobj, run=run)
  File "/home/alex/PycharmProjects/dangjianyun/dangjiansite/dangJianCmd.py", line 312, in thumbTen
    while run.getExcuteTimes()['thumb'] > 0:
  File "/home/alex/PycharmProjects/dangjianyun/dangjiansite/runner.py", line 132, in getExcuteTimes
    credInfo = self.getCredItinfo()
  File "/home/alex/PycharmProjects/dangjianyun/dangjiansite/runner.py", line 232, in getCredItinfo
    info = self.getRJson(url=creditInfourl)
  File "/home/alex/PycharmProjects/dangjianyun/dangjiansite/runner.py", line 190, in getRJson
    return self.session.post(url=url, data=data, verify=False).json()
  File "/home/alex/.local/lib/python3.5/site-packages/requests/sessions.py", line 555, in post
    return self.request('POST', url, data=data, json=json, **kwargs)
  File "/home/alex/.local/lib/python3.5/site-packages/requests/sessions.py", line 508, in request
    resp = self.send(prep, **send_kwargs)
  File "/home/alex/.local/lib/python3.5/site-packages/requests/sessions.py", line 618, in send
    r = adapter.send(request, **kwargs)
  File "/home/alex/.local/lib/python3.5/site-packages/requests/adapters.py", line 490, in send
    raise ConnectionError(err, request=request)
requests.exceptions.ConnectionError: ('Connection aborted.', RemoteDisconnected('Remote end closed connection without response',))
